<?xml version="1.0" ?>

<!-- Fabrizia Auletta -->
<!-- fabrizia.auletta@bristol.ac.uk -->
<!-- June 2020 -->
 
<robot name="agent_diff_drive" xmlns:xacro="http://www.ros.org/wiki/xacro">


  <!--All units in m-kg-s-radians unit system -->
  <xacro:property name="M_PI" value="3.1415926535897931" />
  <xacro:property name="M_PI_2" value="1.570796327" />
  <xacro:property name="DEG_TO_RAD" value="0.017453293" />

	<!--Material Definition-->  
	<material name="Black">
	  <color rgba="0.0 0.0 0.0 1.0"/>
	</material>

  <material name="Red">
  	<color rgba="0.8 0.0 0.0 1.0"/>
  </material>

  <material name="White">
    <color rgba="1.0 1.0 1.0 1.0"/>
  </material>

  <material name="Blue">
    <color rgba="0.0 0.0 0.8 1.0"/>
  </material>
	<!-- -->

  <!-- Base properties -->0.445 0.277 0.17
  
  <xacro:property name="base_length" value="0.5" /> <!-- x-->
  <xacro:property name="base_width" value="0.3" /> <!-- y-->
  <xacro:property name="base_height" value="0.25" /> <!-- z-->
  <xacro:property name="base_mass" value="5" />

  <!-- caster wheel proprieties  -->
  <xacro:property name="caster_height" value="0.05" /> 
  <xacro:property name="caster_radius" value="0.05" /> 
  <xacro:property name="caster_mass" value="1" /> <!-- in kg-->

  <!-- Wheels -->
  <xacro:property name="wheel_radius" value="0.1" /> 
  <xacro:property name="wheel_height" value="0.04" />
  <xacro:property name="wheel_mass" value="2.5" /> <!-- in kg-->
  
  <xacro:property name="base_x_origin_to_wheel_origin" value="0.15" />
  <xacro:property name="base_y_origin_to_wheel_origin" value="0.15" />
  <xacro:property name="base_z_origin_to_wheel_origin" value="-0.1" />
  

  <xacro:macro name="box_inertia" params="m x y z">
    <inertia  ixx="${m*(y*y+z*z)/12}" ixy = "0" ixz = "0"
              iyy="${m*(x*x+z*z)/12}" iyz = "0"
              izz="${m*(x*x+y*y)/12}" /> 
  </xacro:macro>

  <xacro:macro name="cylinder_inertia" params="m r h">
    <inertia  ixx="${m*(3*r*r+h*h)/12}" ixy = "0" ixz = "0"
              iyy="${m*(3*r*r+h*h)/12}" iyz = "0"
              izz="${m*r*r/2}" /> 
  </xacro:macro>


	<xacro:macro name="caster_joint" params="name parent child *origin">
		<joint name="${name}" type="continuous" >
			<parent link="${parent}" />
			<child link="${child}" />
	    <xacro:insert_block name="origin" />
	    <limit effort="100" velocity="100"/>
             <joint_properties damping="0.0" friction="0.0"/>
		</joint>
		
	</xacro:macro>



	<xacro:macro name="caster_link" params="name *origin">
		<link name="${name}">
			<visual>
	    	<xacro:insert_block name="origin" />
				<geometry>
					<sphere radius="${caster_radius}" />
				</geometry>
				
			</visual>  
			<collision>
				<geometry>
					<sphere radius="${caster_radius}" /><!--${M_PI/2}- -->
				</geometry>
				<origin xyz="0 0 0" rpy="0 0 0" />
			</collision>      
			<inertial>
				<mass value="${caster_mass}" />
				<origin xyz="0 0 0" />
					<inertia  ixx="0.001" ixy="0.0" ixz="0.0"
						  			iyy="0.001" iyz="0.0" 
 										izz="0.001" />
			</inertial>
		</link>
		
		<gazebo reference="${name}">
		        <material>Gazebo/Red</material>
	       </gazebo>
		

	</xacro:macro>
	
	<!--fb : front, back ; lr: left, right -->
  <xacro:macro name="wheel" params="fb lr parent translateX translateY flipY"> 
	  <link name="${fb}_${lr}_wheel">
      <visual>
        <origin xyz="0 0 0" rpy="${flipY*M_PI/2} 0  0 " /> 
        <geometry>
          <cylinder length="${wheel_height}" radius="${wheel_radius}" />
        </geometry>
        <material name="DarkGray" />
      </visual>
      <collision>
        <origin xyz="0 0 0" rpy="${flipY*M_PI/2} 0 0 " />
        <geometry>
          <cylinder length="${wheel_height}" radius="${wheel_radius}" />
        </geometry>
      </collision>
      <inertial>
        <mass value="${wheel_mass}" />
        <origin xyz="0 0 0" />
        <cylinder_inertia  m="${wheel_mass}" r="${wheel_radius}" h="${wheel_height}" />
      </inertial>
    </link>
		
    <joint name="${fb}_${lr}_wheel_joint" type="continuous">
      <parent link="${parent}"/>
      <child link="${fb}_${lr}_wheel"/>
      <origin xyz="${translateX * base_x_origin_to_wheel_origin} ${translateY * base_y_origin_to_wheel_origin} ${base_z_origin_to_wheel_origin}" rpy="0 0 0" /> 
      <axis xyz="0 1 0" rpy="0  0" />
      <limit effort="100" velocity="100"/>
      <joint_properties damping="0.0" friction="0.0"/>
    </joint>   


    <!-- Transmission is important to link the joints and the controller -->
    <transmission name="${fb}_${lr}_wheel_joint_trans">
      <type>transmission_interface/SimpleTransmission</type>
      <joint name="${fb}_${lr}_wheel_joint" />
      <actuator name="${fb}_${lr}_wheel_joint_motor">
        <hardwareInterface>EffortJointInterface</hardwareInterface>
        <mechanicalReduction>1</mechanicalReduction>
      </actuator>
    </transmission>
    



    
  </xacro:macro>
  



</robot>
